Workbook

Sheet Summary Sheet
A3: Badders and Liquid Diamond Extracts (Hydrocarbon) | E3: Liquid Diamond Vaporizers | K3: Rosin (Solventless) | Q3: PreRolls (Branded)
A5: Single Batch Figures (1batch = 15lbs) | C5: Trim Cost (can edit) | F5: Liquid Diamonds Vape Cost Summary | L5: Single Batch Fresh Frozen (1batch = 60lbs) | Q5: Cost Percents (1 g raw preroll) | S5: Cost Percents (1 g 30% LD Infused preroll) | V5: Cost Percents (1 g 30% M.D Infused preroll)
A6: Run Size (g) | B6: 6810 | C6: 250 | F6: Figures based on production averages and trim @ $300/lb | G6: 0.5g | H6: 1.0g | L6: Moisture Correction Price Calculator | Q6: Flower @ $1200/lb | S6: Flower @ $1200/lb | V6: Flower @ $1200/lb
A7: Trim cost (g) @$300/lb | B7: =C6/454 -> 0.55066079 | F7: Base Oil | G7: =B22/2 -> 3.0593303 | H7: =B22 -> 6.1186606 | L7: Target Flower Price (Dry) | M7: 1047 | Q7: Rolling Materials + Labor $ | R7: 3.1999194 | S7: Rolling Materials + Labor $ | U7: 6.40279 | V7: Rolling Materials + Labor $ | X7: 5.6117834
A8: Batch Cost | B8: =B6*B7 -> 3750 | F8: Terpenes | G8: 0.1196 | H8: 0.2392 | L8: Target Trim Price Price (Dry) | M8: 300 | Q8: Rolling Materials + Labor % | R8: 0.59346573 | S8: Rolling Materials + Labor % | U8: 0.74496177 | V8: Rolling Materials + Labor % | X8: 0.7191106
A9: Extraction Labor | B9: 50 | F9: Hardware | G9: 1.75 | H9: 1.75 | L9: Avg Trim Yield | M9: 0.3223 | Q9: Packaging Materials $ | R9: 0.33 | S9: Packaging Materials $ | U9: 0.33 | V9: Packaging Materials $ | X9: 0.33
A10: Solvent Cost | B10: 13.72 | F10: Packaging (Raw Inputs) | G10: 1.037 | H10: 1.037 | L10: Cost Allocated Price Per Lb (Dry) | M10: =(M7*(1-M9))+(M8*M9) -> 806.2419 | Q10: Packaging Materials % | R10: 0.061202695 | S10: Packaging Materials % | U10: 0.038395353 | V10: Packaging Materials % | X10: 0.042287181
A11: Processing Labor (badder) | B11: 120 | F11: Labor to Fill | G11: 0.046511628 | H11: 0.046511628 | L11: Fresh Frozen Per Lb Price | M11: =M10*0.2 -> 161.24838 | Q11: Packaging Labor $ | R11: 1.862 | S11: Packaging Labor $ | U11: 1.862 | V11: Packaging Labor $ | X11: 1.862
A12: Processing Labor Diamonds | B12: 180 | F12: Labor to Package | G12: 0.56666667 | H12: 0.56666667 | L12: Run Size (g) | M12: =60*454 -> 27240 | Q12: Packaging Labor % | R12: 0.34533157 | S12: Packaging Labor % | U12: 0.21664287 | V12: Packaging Labor % | X12: 0.23860222
A13: Avg Crude Yield % (from table A) | B13: 0.12 | C13: <-- Can Edit | F13: Compliance Testing (per 600g of oil) | G13: 0.35 | H13: 0.35 | L13: flower cost (g) | M13: =M11/454 -> 0.35517264 | Q13: Total $ | R13: 5.3919194 | S13: Total $ | U13: 8.59479 | V13: Total $ | X13: 7.8037834
A14: Crude Oil Yield (g) | B14: =B13*B6 -> 817.2 | F14: Total | G14: =SUM(G7:G13) -> 6.9291086 | H14: =SUM(H7:H13) -> 10.108039 | L14: Batch Cost | M14: =M13*M12 -> 9674.9028 | Q14: Total % | R14: 1 | S14: Total % | U14: 1 | V14: Total % | X14: 1
A15: Crude Cost(g) | B15: =(B8+B9+B10)/B14 -> 4.6668135 | L15: Extraction Labor | M15: 140
A16: Avg Yield % to Diamonds (From Oil) | B16: 0.35 | C16: <-- Can Edit | L16: Solvent (H20) Cost | M16: 0.735
A17: Diamond Yield (g) | B17: =B14*B16 -> 286.02 | F17: Hardware pricing includes a 22.5% charge for tariffs (2/8/2026) | L17: Processing Labor(Dry and Sift) | M17: 40 | R17: PreRolls (UnBranded)(Raw)
A18: Cost Allocation to Diamonds | B18: =B17*B15+B12 -> 1514.802 | L18: Processing Labor (Rosin Packing) | M18: =20*(M20/675) -> 25.827556 | Q18: PreRoll Formulations (B grade) | R18: Flower Wholesale Price (386g) | S18: Cost Per Gram (F) | T18: Cost per Gram (T) | U18: Flower Cost w/cone | V18: Roll, Mill, QC Labor | W18: Packaging Per PreRoll | X18: Total Cost to Produce | Y18: Joint Wholesale Price | Z18: Profit (Per Unit)
A19: per gram price | B19: =B18/B17 -> 5.2961401 | L19: Avg Bubble Yield % | M19: 0.032 | Q19: 50/50 (Flower:Trim) | R19: 750 | S19: =U19*0.5 -> 1.0015026 | T19: =U19*0.5 -> 1.0015026 | U19: =(R19/386)+0.06 -> 2.0030052 | V19: 0.05 | W19: 0.19662347 | X19: =U19+V19+W19 -> 2.2496287 | Y19: 2.75 | Z19: =Y19-X19 -> 0.50037135
A20: Liquid Diamond Yield | B20: =B17* 0.877 -> 250.83954 | E20: Cured Resin Vaporizers | L20: Bubble Hash Yield (g) | M20: =M12*M19 -> 871.68 | Q20: 30/70 (Flower:Trim) | R20: 570 | S20: =(U20-0.06)*0.3 -> 0.44300518 | T20: =(U20-0.06)*0.7 -> 1.0336788 | U20: =(R20/386)+0.06 -> 1.5366839 | V20: 0.05 | W20: =W19 -> 0.19662347 | X20: =U20+V20+W20 -> 1.7833074 | Y20: 2.75 | Z20: =Y20-X20 -> 0.96669259
A21: cost allocation to liquid diamonds | B21: =(B17*B15)+B12+20 -> 1534.802 | L21: cost allocation to Bubble Hash | M21: =M14+M15+M16+M17 -> 9855.6378
A22: per gram price | B22: =B21/B20 -> 6.1186606 | F22: Vape Cost Summary | L22: per gram price | M22: =M21/M20 -> 11.306486 | R22: PreRolls (UnBranded)(Infused) | Y22: * Pricing does not include corrugated box
A23: Remaing % Crude | B23: =1-B16 -> 0.65 | F23: Figures based on production averages and Trim @ $300.00/lb | G23: 1.0g | H23: Yield | L23: Yield To Rosin % | M23: 0.81 | Y23: 12 x 9 x 6 (Case of 100) | Z23: 0.67
A24: Remaining Crude (g) | B24: =B14*B23 -> 531.18 | F24: Base Oil (Corrected For 13% Decarb Loss) | G24: =B15/0.877 -> 5.3213381 | H24: 0.12 | L24: Rosin Yield (g) | M24: =M20*M23 -> 706.0608 | Q24: Liquid Diamond Economy | U24: Micro Diamond Economy | Y24: 6 x 6 x 6 (Case of 48/50) | Z24: 0.39
A25: cost allocation to crude | B25: =B24*B15+B11 -> 2598.918 | F25: Hardware (landed) | G25: 0.93 | L25: cost allocation to Rosin | M25: =M14+M15+M16+M17+M18 -> 9881.4654
A26: per gram cost | B26: =B25/B24 -> 4.8927256 | F26: Packaging (Raw Inputs)[poptop only] | G26: 0.05 | L26: per gram cost | M26: =M25/M24 -> 13.995205 | Q26: Cost Percents (1 g 30% LD Infused preroll) | U26: Cost Percents (1 g 30% M.D Infused preroll)
A27: Cost to Produce Hydrocarbon (Cured Badder) | F27: Labor to Fill | G27: 0.046511628 | Q27: 50/50 Flower @ $1200/lb Trim @ $300/lb | U27: 50/50 Flower @ $1200/lb Trim @ $300/lb
A28: Figures based on production averages and trim @ $300/lb | B28: 1.0g | C28: 3.5g | F28: Labor to Package | G28: 0.08 | L28: Live Hash Rosin COGs | Q28: Rolling Materials + Labor $ | S28: 2.0510458 | U28: Rolling Materials + Labor $ | W28: 2.0510458
A29: Crude | B29: =B26 -> 4.8927256 | C29: =B26*3.5 -> 17.12454 | F29: Compliance Testing (per 1500 units) ($460.28) | G29: =460.28/1800 -> 0.25571111 | L29: Figures based on production averages, dry flower equivalent @ $1,200/lb and trim @ $300/lb | M29: 1.0g | N29: 2.0g | Q29: Rolling Materials + Labor % | S29: 0.38603154 | U29: Rolling Materials + Labor % | W29: 0.43399222
A30: Packaging (Raw Inputs) | B30: 1.1897799 | C30: 1.1897799 | L30: Rosin | M30: =M26 -> 13.995205 | N30: =M30*2 -> 27.990409 | Q30: Infusion Strength | S30: 0.3 | U30: Infusion Strength | W30: 0.3
A31: Labor to Fill | B31: 0.31 | C31: 0.3875 | F31: Total | G31: =SUM(G24:G29) -> 6.6835608 | L31: Packaging (Raw Inputs) | M31: 1.1897799 | N31: 1.1897799 | Q31: Infusion Cost (Used Value from Material Costs Table) | S31: 3.0831102 | U31: Infusion Cost (Used Value from Material Costs Table) | W31: 2.4989509
A32: Labor to Package | B32: 0.12626263 | C32: 0.12626263 | L32: Labor to Fill | M32: 0.31 | N32: 0.31 | Q32: Infusion Cost % | S32: 0.5802785 | U32: Infusion Cost Percent | W32: 0.52876696
A33: R/D Testing | B33: 0.75488697 | C33: 0.75488697 | L33: Labor to Package | M33: 0.8 | N33: 0.8 | Q33: Packaging Materials $ | S33: 0.113 | U33: Packaging Materials $ | W33: 0.11
A34: Compliance Testing | B34: 0.567675 | C34: 0.567675 | L34: Compliance Testing | M34: 0.64918192 | N34: 0.64918192 | Q34: Packaging Materials % | S34: 0.021267962 | U34: Packaging Materials % | W34: 0.023275513
A35: Total | B35: =SUM(B29:B34) -> 7.8413301 | C35: =SUM(C29:C34) -> 20.150644 | L35: Total | M35: =SUM(M30:M34) -> 16.944166 | N35: =SUM(N30:N34) -> 30.939371 | Q35: Packaging Labor $ | S35: 0.082 | U35: Packaging Labor $ | W35: 0.082
E36: Live Rosin Vaporizers | Q36: Packaging Labor % | S36: 0.012421995 | U36: Packaging Labor % | W36: 0.013965308
L37: *Adjust Highlighted Values to Determine Infusion Costs | Q37: Total $ | S37: 5.313156 | U37: Total $ | W37: 4.7259967
F38: Liquid Diamonds Vape Cost Summary | L38: Single Batch Trim Run (1batch = 45lbs) | Q38: Total % | S38: 1 | U38: Total % | W38: 1
F39: Figures based on production averages and F.Frozen @ $909.93/lb | G39: 0.5g | L39: Target Trim Price Price (Dry) | M39: 800
F40: Base Oil (Corrected For 13% Decarb Loss) | G40: =(M26/0.87)*0.5 -> 8.043221 | L40: Run Size (g) | M40: =45*454 -> 20430 | Q40: Cost Percents (1 g 30% LD Infused preroll) | U40: Cost Percents (1 g 30% M.D Infused preroll)
F41: Hardware | G41: 1.75 | L41: flower cost (g) | M41: =M39/454 -> 1.7621145 | Q41: 30/70 Flower @ $1200/lb Trim @ $300/lb | U41: 30/70 Flower @ $1200/lb Trim @ $300/lb
F42: Packaging (Raw Inputs) | G42: 1.037 | L42: Batch Cost | M42: =M41*M40 -> 36000 | Q42: Rolling Materials + Labor $ | S42: 1.4875743 | U42: Rolling Materials + Labor $ | W42: 1.4875743
F43: Labor to Fill | G43: 0.046511628 | L43: Extraction Labor | M43: 140 | Q43: Rolling Materials + Labor % | S43: 0.31319434 | U43: Rolling Materials + Labor % | W43: 0.35737304
...

Sheet Rosin PricingYield
A4: Low Yield Scenario 2.8%
A5: Single Batch Fresh Frozen (1batch = 60lbs) | D5: Live Hash Rosin COGs
A6: Moisture Correction Price Calculator | D6: Figures based on production averages, dry flower equivalent @ $1,200/lb and trim @ $300/lb | E6: 1.0g | F6: 2.0g
A7: Target Flower Price (Dry) | B7: 741 | C7: =CHAR(8592) -> ← | D7: Rosin | E7: =B26 -> 12.0542 | F7: =E7*2 -> 24.1084
A8: Target Trim Price Price (Dry) | B8: 300 | D8: Packaging (Raw Inputs) | E8: 1.1897799 | F8: 1.1897799
A9: Avg Trim Yield | B9: 0.3223 | D9: Labor to Fill | E9: 0.31 | F9: 0.31
A10: Cost Allocated Price Per Lb (Dry) | B10: =(B7*(1-B9))+(B8*B9) -> 598.8657 | D10: Labor to Package | E10: 0.8 | F10: 0.8
A11: Fresh Frozen Per Lb Price | B11: =B10*0.2 -> 119.77314 | D11: Compliance Testing | E11: 0.64918192 | F11: 0.64918192
A12: Run Size (g) | B12: =60*454 -> 27240 | D12: Total | E12: =SUM(E7:E11) -> 15.003162 | F12: =SUM(F7:F11) -> 27.057362
A13: flower cost (g) | B13: =B11/454 -> 0.26381749
A14: Batch Cost | B14: =B13*B12 -> 7186.3884
A15: Extraction Labor | B15: 140
A16: Solvent (H20) Cost | B16: 0.735
A17: Processing Labor(Dry and Sift) | B17: 40
A18: Processing Labor (Rosin Packing) | B18: 80
A19: Avg Bubble Yield % | B19: 0.028
A20: Bubble Hash Yield (g) | B20: =B12*B19 -> 762.72
A21: cost allocation to Bubble Hash | B21: =B14+B15+B16+B17 -> 7367.1234
A22: per gram price | B22: =B21/B20 -> 9.6590143
A23: Yield To Rosin % | B23: 0.81
A24: Rosin Yield (g) | B24: =B20*B23 -> 617.8032
A25: cost allocation to Rosin | B25: =B14+B15+B16+B17+B18 -> 7447.1234
A26: per gram cost | B26: =B25/B24 -> 12.0542
A28: Target Minimum Yield Scenario 3.5%
A30: Single Batch Fresh Frozen (1batch = 60lbs) | D30: Live Hash Rosin COGs
A31: Moisture Correction Price Calculator | D31: Figures based on production averages, dry flower equivalent @ $1,200/lb and trim @ $300/lb | E31: 1.0g | F31: 2.0g
A32: Target Flower Price (Dry) | B32: 970 | D32: Rosin | E32: =B51 -> 12.054898 | F32: =E32*2 -> 24.109795
A33: Target Trim Price Price (Dry) | B33: 300 | D33: Packaging (Raw Inputs) | E33: 1.1897799 | F33: 1.1897799
A34: Avg Trim Yield | B34: 0.3223 | D34: Labor to Fill | E34: 0.31 | F34: 0.31
A35: Cost Allocated Price Per Lb (Dry) | B35: =(B32*(1-B34))+(B33*B34) -> 754.059 | D35: Labor to Package | E35: 0.8 | F35: 0.8
A36: Fresh Frozen Per Lb Price | B36: =B35*0.2 -> 150.8118 | D36: Compliance Testing | E36: 0.64918192 | F36: 0.64918192
A37: Run Size (g) | B37: =60*454 -> 27240 | D37: Total | E37: =SUM(E32:E36) -> 15.00386 | F37: =SUM(F32:F36) -> 27.058757
A38: flower cost (g) | B38: =B36/454 -> 0.33218458
A39: Batch Cost | B39: =B38*B37 -> 9048.708
A40: Extraction Labor | B40: 140
A41: Solvent (H20) Cost | B41: 0.735
A42: Processing Labor(Dry and Sift) | B42: 40
A43: Processing Labor (Rosin Packing) | B43: 80
A44: Avg Bubble Yield % | B44: 0.035
A45: Bubble Hash Yield (g) | B45: =B37*B44 -> 953.4
...

Sheet Volatile IN_OUT
G1: Single Batch Figures (1batch = 15lbs) | O1: PostProcessing Costs (Diamonds)
A2: Luna Throughput | B2: 8 | C2: lbs per run | G2: Run Size (g) | H2: 6810 | O2: Cost of Input Oil | P2: =(B4*B8*B18)+(B15*B39)+(B14*B17) -> 3065.56
A3: Hours Per Run | B3: 2.5 | C3: hour(s) | G3: Trim cost (g) @$300/lb | H3: =300/454 -> 0.66079295 | O3: Added Costs
A4: # of operators | B4: 1 | C4: person | G4: Batch Cost | H4: =H3*H2 -> 4500 | I4: Cost to Produce Hydrocarbon (Cured Badder) | O4: Tech (cost of maturation) | P4: =B18*P6 -> 140
A5: WorkDays/week | B5: 4 | C5: days | G5: Extraction Labor | H5: =(B18*B3) -> 50 | I5: Figures based on production averages and trim @ $300/lb | J5: 1.0g | K5: 3.5g | O5: Maturation Time | P5: 7 | Q5: Days
A6: WorkDays/year | B6: =(B5*52)-B7 -> 198 | C6: days | G6: Solvent Cost | H6: =B17*B14 -> 13.72 | I6: Crude | J6: =H22 -> 6.3387203 | K6: =H22*3.5 -> 22.185521 | O6: Hours to Complete | P6: =P5*1 -> 7 | Q6: hours
A7: Holidays per Year | B7: 10 | C7: days | G7: Processing Labor (badder) | H7: 120 | I7: Packaging (Raw Inputs) | J7: =B24+D33 -> 1.1897799 | K7: =B24+D33 -> 1.1897799 | O7: Storage | P7: 0
A8: Hours in workday | B8: 7 | C8: hours | G8: Processing Labor Diamonds | H8: =B18*9 -> 180 | I8: Labor to Fill | J8: =F23 -> 0.31 | K8: =F23+(F23*0.25) -> 0.3875 | O8: Total Cost | P8: =P2+P4+P7 -> 3205.56
A9: Runs per day | B9: =(B8-2)/B3 -> 2 | C9: runs/day | G9: Avg Crude Yield % (from table A) | H9: 0.11 | I9: Labor to Package | J9: =F24 -> 0.12626263 | K9: =F24 -> 0.12626263 | O9: Diamond Yield (from crude) | P9: 0.75 | R9: 11.85
A10: Runs per year | B10: =B9*B6 -> 396 | C10: runs/year | G10: Crude Oil Yield (g) | H10: =H2*H9 -> 749.1 | I10: R/D Testing | J10: =B27/H20 -> 1.0268733 | K10: =B27/H20 -> 1.0268733 | O10: Diamond Yield (from flower) | P10: =P11/B39 -> 0.0748125
A11: Extraction Efficiency | B11: 0.75 | C11: efficient | G11: Crude Oil Cost (g) | H11: =(H4+H5+H6)/H10 -> 6.0922707 | I11: Compliance Testing | J11: =B28/H20 -> 0.7722087 | K11: =J11 -> 0.7722087 | O11: Total Diamond Output | P11: =B48*P9 -> 1.197 | Q11: lbs
A12: Flower THC % | B12: 0.133 | C12: cannabinoids | G12: Avg Yield % to Diamonds (From Oil) | H12: 0.35 | I12: Total | J12: =SUM(J6:J9) -> 7.9647628 | K12: =SUM(K6:K9) -> 23.889064 | P12: =P11*454 -> 543.438 | Q12: grams
A13: Yield % | B13: =B12*B11 -> 0.09975 | C13: THC Oil | G13: Diamond Yield (g) | H13: =H10*H12 -> 262.185 | O13: Cost Per Gram | P13: =P8/P12 -> 5.8986674
A14: solvent loss | B14: 4 | C14: lb/run | G14: Cost Allocation to Diamonds | H14: =H13*(($H$4+$H$5+$H$6)/$H$10) -> 1597.302
A15: Wholesale Biomass (lb) | B15: 181.99 | C15: per lb | G15: per gram price | H15: =H14/H13 -> 6.0922707 | O15: Liquid Diamond Yield (100% oil to diamonds)
A16: Wholesale Oil | B16: 15 | C16: per gram | G16: Liquid Diamond Yield | H16: =H13*0.877 -> 229.93625 | O16: Conversion Rate | P16: 0.877
A17: solvent price (lb) | B17: 3.43 | C17: lb | G17: cost allocation to liquid diamonds | H17: =H14+$H$8 -> 1777.302 | P17: =P12*0.877 -> 476.59513 | Q17: grams
A18: employee salary | B18: 20 | C18: hour | G18: per gram price | H18: =H17/H16 -> 7.7295426 | P18: =P17/454 -> 1.049769 | Q18: lbs
G19: Remaing % Crude | H19: =100%-H12 -> 0.65 | O19: Cost to Converted Oil (per gram) | P19: =P8/P17 -> 6.7259605
A20: Packaging Costs (Inputs) | G20: Remaining Crude (g) | H20: =H10-H13 -> 486.915
A21: Glass Jar | B21: 0.4 | D21: Packaging Costs (Labor) | E21: Rate/min | F21: Cost | G21: cost allocation to crude | H21: =H20*(($H$4+$H$5+$H$6)/$H$10)+$H$7 -> 3086.418 | O21: Liquid Diamonds to Vape (Daily)
A22: Primary Box | B22: 0.64 | D22: Labor Rate ($/hr) | E22: 20 | G22: per gram cost | H22: =H21/H20 -> 6.3387203 | O22: % Diamond Allocation | P22: 1 | Q22: % oil to Market | R22: 0
A23: Outer Box | B23: 0.04 | D23: Hand Filling Rate (jars/min) | E23: =60/65 -> 0.92307692 | F23: 0.31 | O23: Total oil to diamonds | P23: =B49*P22 -> 724.584 | Q23: Total oil to market | R23: =B49*R22 -> 0
A24: Total Cost of Packaging | B24: =SUM(B21:B23) -> 1.08 | D24: Master Casing Rate (boxes/min) | E24: 0.66 | F24: =(1/E24)/12 -> 0.12626263 | O24: yield % diamonds from oil (= P9) | P24: =P9 -> 0.75
D25: Total | F25: =SUM(F23:F24) -> 0.43626263 | O25: Diamond yield | P25: =P24*P23 -> 543.438
A26: Testing Cost (Safetiva 2025) | O26: Total Liquid Diamonds | P26: =(P25)*0.877 -> 476.59513 | Q26: loss from decarb | R26: =-((P25)-P26) -> -66.842874 | S26: grams
A27: R/D Residual Solvents | B27: 500
A28: Compliance | B28: =470-(470*0.2) -> 376
A30: Labeling Costs | B30: Case Cost | C30: Labels Per Case | D30: Per Unit Cost | O30: Liquid Diamonds to Vape (Monthly)
A31: 2.25x1.25 Label | B31: 14.98 | C31: =1135*4 -> 4540 | D31: =B31/C31 -> 0.0032995595 | O31: % Diamond Allocation | P31: 1 | Q31: % oil to Market | R31: 0
A32: Black Ribbon | B32: 83.8 | C32: 787 | D32: =B32/C32 -> 0.1064803 | O32: Total oil to diamonds | P32: =B53*P31 -> 14491.68 | Q32: Total oil to market | R32: =B53*R31 -> 0
A33: Total | D33: =SUM(D31:D32) -> 0.10977986 | O33: yield % diamonds from oil (= P9) | P33: =P9 -> 0.75
O34: Diamond yield | P34: =P33*P32 -> 10868.76
O35: Total Liquid Diamonds | P35: =(P34)*0.877 -> 9531.9025 | Q35: loss from decarb | R35: =-(P34-P35) -> -1336.8575 | S35: grams
A37: Output and Projected Costs/Revenue
A38: # of runs/day | B38: =B9 -> 2
A39: Total Biomass needed | B39: =B2*B38 -> 16 | C39: lbs
A40: Biomass needed weekly | B40: =B39*B5 -> 64 | C40: lbs
A42: Input cost (Daily) | B42: =(B4*B8*B18)+(B15*B39)+(B14*B17) -> 3065.56
A43: Cost per Gram | B43: =B42/B49 -> 4.2307862 | C43: per gram
...

Sheet VAPE 
A1: Vape Production (Liquid Diamonds)
A2: Costs
J3: Totals Calculations (1.0g) | K3: Monthly | O3: Totals Calculations (0.5g) | P3: Per Unit
A4: Input Oil (From Volatile wkst) | B4: ='Volatile IN_OUT'!H18 -> 7.7295426 | C4: per gram | F4: Required Inputs (Monthly) | G4: 1.0 g Carts | J4: Oil | K4: =G6*B4 -> 0 | O4: Oil | P4: =(B4*(1-G7))*0.5 -> 3.5555896 | Q4: =P4/P13 -> 0.52273634
A5: Terpene- Botanical (50 g bottle) | B5: 2.99 | C5: per gram | F5: Hardware Filled | G5: 0 | H5: units | J5: Hardware | K5: =G5*B8 -> 0 | O5: Hardware | P5: =B8 -> 1.43 | Q5: =P5/P13 -> 0.21023601
A6: Terpene- Cannabis | B6: ='Volatile IN_OUT'!E53 -> 0.1523083 | C6: per gram | F6: Oil | G6: =G5*1 -> 0 | H6: g | J6: Terps | K6: =G8*B5 -> 0 | O6: Terps | P6: =(B5*G21)*0.5 -> 0.1196 | Q6: =P6/P13 -> 0.017583375
A7: Tec-Temper | B7: =359/250 -> 1.436 | C7: per gram | F7: Terp Dilution | G7: 0.08 | J7: Temper | K7: =G10*B7 -> 0 | O7: Temper | P7: =B7*G23 -> 0 | Q7: =P7/P13 -> 0
A8: Hardware | B8: =1.18+0.25 -> 1.43 | C8: per unit | F8: Terps | G8: =G6*G7 -> 0 | H8: g | J8: Labor | K8: =G5*B10 -> 0 | O8: Labor (Formulation) | P8: =B10 -> 0.046511628 | Q8: =P8/P13 -> 0.0068380552
A9: Labor | B9: 20 | C9: per hour | F9: Temper Dilution | G9: 0 | J9: Packaging | K9: =G5*B11 -> 0 | O9: Packaging (Raw Materials) | P9: =B11 -> 1.037 | Q9: =P9/P13 -> 0.15245786
A10: Per Unit Labor | B10: =B9/B16 -> 0.046511628 | C10: per unit | F10: Temper | G10: =G9*G6 -> 0 | H10: g | L10: Wholesale Price | M10: =B15 -> 12 | O10: Labor (Filling) | P10: =B17 -> 0.046511628 | Q10: =P10/P13 -> 0.0068380552
A11: Packaging (Provided by Josie) | B11: =0.55+0.05+0.25+0.117+0.01+0.06 -> 1.037 | C11: per unit | J11: Total Cost | K11: =SUM(K4:K10) -> 0 | L11: Projected Revenue | M11: =M10*G5 -> 0 | O11: Labor (Packaging) | P11: =C24 -> 0.56666667 | Q11: =P11/P13 -> 0.083310306
J12: Cost Per Unit | K12: =K11/G5 -> #DIV/0! | L12: Projected Profit | M12: =M11-K11 -> 0
A13: Production | F13: *Check Value of oil to Production Volume | J13: Total Cost (-oil) | K13: =SUM(K5:K9) -> 0 | L13: Margin | M13: =(M11-K11)/M11 -> #DIV/0! | O13: Total Cost | P13: =SUM(P4:P12) -> 6.8018795
A14: Wholesale Price (.5g) | B14: 8 | F14: oil remaining | G14: =B19-(G6+G20) -> 9301.9025 | J14: Total Cost (-hardware & oil) | K14: =SUM(K6:K9) -> 0 | O14: Wholesale Price | P14: 13.5
A15: Wholesale Price (1g) | B15: 12 | O15: Margin | P15: =(P14-P13)/P13 -> 0.98474553
A16: Filling Speed (units/hr) | B16: 430 | F16: Required Inputs (Monthly) | G16: 0.5 g Carts
A17: Filling Labor Cost (per unit) | B17: =B9/B16 -> 0.046511628 | O17: Liquid Diamonds Vape Cost Summary
A18: Suggested Toll Fill Price | B18: 2.5 | O18: Figures based on production averages and trim @ $300/lb | P18: 0.5g | Q18: 1.0g
A19: Volume of Oil to Vapes (Monthly) | B19: ='Volatile IN_OUT'!P35 -> 9531.9025 | F19: Hardware Filled | G19: 500 | H19: units | O19: Base Oil | P19: =P4 -> 3.5555896 | Q19: 4.5
A20: Packaging Labor | B20: Time (Min) | C20: Cost (Unit) | F20: Oil | G20: =(G19*0.5)-G22 -> 230 | H20: g | O20: Terpenes | P20: =P6 -> 0.1196 | Q20: =P20*2 -> 0.2392
A21: Plastic Removal | B21: 0.2 | C21: =(B9/60)*B21 -> 0.066666667 | F21: Terp Dilution | G21: 0.08 | O21: Hardware | P21: =B8 -> 1.43 | Q21: 0.92
A22: Sticker Application | B22: 0.75 | C22: =(B9/60)*B22 -> 0.25 | F22: Terps | G22: =(G19*0.5)*G21 -> 20 | H22: g | O22: Packaging (Raw Inputs) | P22: =P9 -> 1.037 | Q22: 0.07
A23: Tube Fill and Insert Placement | B23: 0.75 | C23: =(B9/60)*B23 -> 0.25 | F23: Temper Dilution | G23: 0 | O23: Labor to Fill | P23: =P10 -> 0.046511628 | Q23: =P10 -> 0.046511628
A24: Total Cost | C24: =SUM(C21:C23) -> 0.56666667 | F24: Temper | G24: =G23*G20 -> 0 | H24: g | O24: Labor to Package | P24: =P11 -> 0.56666667 | Q24: 0.25
O25: Compliance Testing (per 600g of oil) | P25: =420/(600*2) -> 0.35 | Q25: =P25*2 -> 0.7
O26: Total | P26: =SUM(P19:P24) -> 6.7553679 | Q26: =SUM(Q19:Q24) -> 6.0257116

Sheet H2O IN_OUT
A1: Cost of Unit | B1: 275000 | G1: Single Batch Figures (1batch = 45lbs)
A2: Throughput (FF) | B2: 20 | C2: lbs per run | G2: Moisture Correction Price Calculator
A3: Hours Per Run | B3: 3 | C3: hour | D3: Avg Trim Yield = 32.23% | G3: Target Flower Price (Dry) | H3: 1300
A4: # of operators | B4: 1 | C4: person | G4: Target Trim Price Price (Dry) | H4: 300 | P4: # of run/day | Q4: 2
A5: WorkDays/week | B5: 4 | C5: days | G5: Avg Trim Yield | H5: 0.3223 | J5: Cost to Produce Live Hash Rosin | P5: Total Biomass needed | Q5: =B2*Q4 -> 40 | R5: lbs
A6: WorkDays/year | B6: =(B5*52)-B7 -> 198 | C6: days | G6: Cost Allocated Price Per Lb (Dry) | H6: =(H3*(1-H5))+(H4*H5) -> 977.7 | J6: ="Figures based on production averages, dry flower equivalent @ $" & TEXT(H3,"#,##0") & "/lb and trim @ $" & TEXT(H4,"#,##0") & "/lb" -> Figures based on production averages, dry flower equivalent @ $1,300/lb and trim @ $300/lb | K6: 1.0g | L6: 2.0g | P6: Conversion | Q6: =Q5*454 -> 18160 | R6: grams
A7: Holidays per Year | B7: 10 | C7: days | G7: Fresh Frozen Per Lb Price | H7: =H6*0.2 -> 195.54 | J7: Rosin | K7: =H22 -> 16.956813 | L7: =K7*2 -> 33.913626 | P7: Biomass needed weekly | Q7: =Q5*B5 -> 160 | R7: lbs
A8: Hours in workday | B8: 7 | C8: hours | G8: Run Size (g) | H8: =45*454 -> 20430 | J8: Packaging (Raw Inputs) | K8: =B32+D41 -> 1.1897799 | L8: =K8 -> 1.1897799
A9: Runs per day | B9: 2 | C9: runs/day | G9: flower cost (g) | H9: =H7/454 -> 0.43070485 | J9: Labor to Fill | K9: =F31 -> 0.14685315 | L9: =K9 -> 0.14685315 | P9: Cost/Profit
A10: Runs per year | B10: =B9*B6 -> 396 | C10: runs/year | G10: Batch Cost | H10: =H9*H8 -> 8799.3 | J10: Labor to Package | K10: =F32 -> 0.84 | L10: =K10 -> 0.84 | P10: Cost of Production (Daily) | Q10: =(B4*B8*B18)+(Q5*B13)+(B12*B17) -> 9740.3675
A11: Yield % | B11: 0.03 | C11: cannabinoids | G11: Extraction Labor | H11: =B18*B8 -> 140 | J11: Compliance Testing | K11: =B36/H20 -> 0.71004272 | L11: =K11 -> 0.71004272 | P11: Cost per Gram | Q11: =Q10/Q18 -> 17.878795 | S11: Time to Pay off Unit
A12: Water Used Per Run | B12: 75 | C12: gallons | G12: Solvent (H20) Cost | H12: =B17*(B12*B9) -> 0.735 | J12: Total | K12: =SUM(K7:K10) -> 19.133446 | L12: =SUM(L7:L10) -> 36.090259 | P12: Revenue (Daily) | Q12: =Q18*B14 -> 5448 | S12: =B1/Q13 -> -64.067208 | T12: days
A13: Wholesale Biomass | B13: 240 | C13: per lb | G13: Processing Labor(Dry and Sift) | H13: =B18*1 -> 20 | P13: Profit | Q13: =Q12-Q10 -> -4292.3675
A14: Wholesale Bubble | B14: 10 | C14: per gram | G14: Processing Labor (Rosin Packing) | H14: =B18*(H16/675) -> 19.370667 | P14: Margin | Q14: =(Q13/Q12) -> -0.7878795
A15: Wholesale Rosin | B15: 15 | C15: per gram | G15: Avg Bubble Yield % | H15: 0.032
A16: Cost of Packaging | B16: 2 | C16: per gram | G16: Bubble Hash Yield (g) | H16: =H8*H15 -> 653.76
A17: water price | B17: 0.0049 | C17: per gallon | D17: *based on >30K gal rate | G17: cost allocation to Bubble Hash | H17: =H10+H11+H12+H13 -> 8960.035 | P17: Total Bubble Output Daily | Q17: =(B2*B11)*B9 -> 1.2 | R17: lbs
A18: employee salary | B18: 20 | C18: hour | G18: per gram price | H18: =H17/H16 -> 13.705389 | P18: Grams | Q18: =Q17*454 -> 544.8
G19: Yield To Rosin % | H19: 0.81 | P19: Total Weekly | Q19: =Q17*5 -> 6 | R19: lbs
A20: Rosin Yield (Daily) | G20: Rosin Yield (g) | H20: =H16*H19 -> 529.5456 | P20: Grams | Q20: =Q19*454 -> 2724
A21: Time per Press | B21: 120 | C21: seconds | G21: cost allocation to Rosin | H21: =H10+H11+H12+H13+H14 -> 8979.4057 | P21: Annual Yield | Q21: =Q17*B6 -> 237.6 | R21: lbs
A22: Grams per Press | B22: 40 | C22: grams | G22: per gram cost | H22: =H21/H20 -> 16.956813 | P22: Grams | Q22: =Q21*454 -> 107870.4
A23: Required Pressing Time | B23: =(B24*B21)/3600 -> 0.454 | C23: Hours
A24: Required Presses | B24: =Q18/B22 -> 13.62 | C24: presses/shift | P24: Quarterly Output | Q24: =Q20*12 -> 32688 | R24: grams
A25: Total Bubble Pressed | B25: =Q18 -> 544.8 | C25: grams | Q25: =Q24/454 -> 72 | R25: lbs
A26: Yield % (Bubble) | B26: 0.85
A27: Yield From Bubble | B27: =B25*B26 -> 463.08 | C27: grams | P27: Cost/Profit (Rosin)
A28: Conversion | B28: =B27/454 -> 1.02 | C28: pounds | P28: Cost of Production (Daily) | Q28: =Q10+(B23*B18)+(B16*B27) -> 10675.608
A29: Glass Jar | B29: 0.4 | D29: Packaging Costs (Labor) | E29: Rate/min | F29: Cost
A30: Primary Box | B30: 0.64 | D30: Labor Rate ($/hr) | E30: 21 | P30: Cost per Gram | Q30: =Q28/B27 -> 23.053484
A31: Outer Box | B31: 0.04 | D31: Hand Filling Rate (jars/min) | E31: =143/60 -> 2.3833333 | F31: =E30/(E31*60) -> 0.14685315 | P31: Gross Revenue (Daily) | Q31: =B27*B15 -> 6946.2
A32: Total Cost of Packaging | B32: =SUM(B29:B31) -> 1.08 | D32: Master Casing Rate (boxes/min) | E32: =12/5 -> 2.4 | F32: =E32*(E30/60) -> 0.84 | P32: Net Revenue | Q32: =Q31-Q28 -> -3729.4075
D33: Total | F33: =SUM(F31:F32) -> 0.98685315 | P33: Margin | Q33: =Q32/Q31 -> -0.53689895
A34: Testing Cost
A35: R/D Residual Solvents | B35: 500
A36: Compliance | B36: =470-(470*0.2) -> 376
A38: Labeling Costs | B38: Case Cost | C38: Labels Per Case | D38: Per Unit Cost
A39: 2.25x1.25 Label | B39: 14.98 | C39: =1135*4 -> 4540 | D39: =B39/C39 -> 0.0032995595
A40: Black Ribbon | B40: 83.8 | C40: 787 | D40: =B40/C40 -> 0.1064803
A41: Total | D41: =SUM(D39:D40) -> 0.10977986

Sheet PREROLL IN_OUT
A1: PreRoll-ER Revenue (Toll) | D1: Flower Cost | E1: 1200 | G1: Cost Per Unit (inputs) | H1: 0.35g | I1: 1g | J1: 1g (b.hash @20%) | K1: 1g(m.diamonds@30%) | L1: 1g(l.diamonds)
D2: Trim Cost | E2: 300 | G2: cone+flower+infusion | H2: =C13+(B15*0.35)+(B8/I7) -> 0.69400115 | I2: =B13+(B15*B11) -> 1.7698446 | J2: =D13+(B15*B11*J13)+(B19*J12)+(B8/J7) -> 5.0522867 | K2: =D13+(B15*B11*K13)+(C19*K12)+(B7/K6) -> 3.9612391 | L2: =D13+(B15*1.1*L13)+(D19*L12)+(B7/L6) -> 4.5772949
A3: Labor Costs (Rolling) | D3: Flower Percent | E3: 0.4 | G3: Production Totals | N3: Cost Percents (1 g raw preroll) | Q3: Cost Percents (1 g 30% LD Infused preroll) | U3: Cost Percents (1 g 30% M.D Infused preroll)
A4: Workday Hours | B4: 7 | C4: hours | D4: Trim Percent | E4: =1-E3 -> 0.6 | H4: (.35g) | I4: (1.0g) | J4: 1g (b.hash) | K4: 1g (diamond) | L4: 1g (l.diamond) | N4: Flower @ $1200/lb | Q4: Flower @ $1200/lb | U4: Flower @ $1200/lb
A5: Workdays (week) | B5: 5 | C5: days | D5: Total Cost | E5: =(E1*E3)+(E2*E4) -> 660 | G5: Rolled Per Min | H5: 20 | I5: 15 | J5: 10 | K5: 10 | L5: 9 | N5: Rolling Materials + Labor $ | O5: =I2+(B7/I6) -> 1.8009557 | Q5: Rolling Materials + Labor $ | S5: =L2 -> 4.5772949 | U5: Rolling Materials + Labor $ | W5: =K2 -> 3.9612391
A6: Workdays (month) | B6: =B5*4 -> 20 | C6: days | G6: Rolled Per Hour | H6: =H5*60 -> 1200 | I6: =I5*60 -> 900 | J6: =J5*60 -> 600 | K6: =K5*60 -> 600 | L6: =L5*60 -> 540 | N6: Rolling Materials + Labor % | O6: =O5/O11 -> 0.45103322 | Q6: Rolling Materials + Labor % | S6: =S5/S11 -> 0.67618489 | U6: Rolling Materials + Labor % | W6: =W5/W11 -> 0.64376486
A7: Labor Rate | B7: 28 | C7: an hour | G7: Total Daily | H7: =B4*H6 -> 8400 | I7: =I6*B4 -> 6300 | J7: =J6*B4 -> 4200 | K7: =J6*B4 -> 4200 | L7: =L6*B4 -> 3780 | N7: Packaging Materials $ | O7: 0.33 | Q7: Packaging Materials $ | S7: 0.33 | U7: Packaging Materials $ | W7: 0.33
A8: Daily Labor Cost | B8: =B7*8 -> 224 | G8: Weekly Total | H8: =H7*B5 -> 42000 | I8: =I7*B5 -> 31500 | J8: =J7*B5 -> 21000 | K8: =J7*B5 -> 21000 | L8: =L7*B5 -> 18900 | N8: Packaging Materials % | O8: =O7/O11 -> 0.082645546 | Q8: Packaging Materials % | S8: =S7/S11 -> 0.048749538 | U8: Packaging Materials % | W8: =W7/W11 -> 0.053630291
A9: Monthly Labor Cost | B9: =B8*B6 -> 4480 | G9: Monthly | H9: =H8*4 -> 168000 | I9: =I8*4 -> 126000 | J9: =J8*4 -> 84000 | K9: =K8*4 -> 84000 | L9: =L8*4 -> 75600 | N9: Packaging Labor $ | O9: 1.862 | Q9: Packaging Labor $ | S9: 1.862 | U9: Packaging Labor $ | W9: 1.862
A10: Material Costs | G10: Required Flower (Daily) | H10: =C11*H7 -> 2940 | I10: =B11*I7 -> 6300 | J10: =(J7*B11)-J14 -> 3360 | K10: =(J7*B11)-K14 -> 2940 | L10: =(B11*L7)-L14 -> 2646 | N10: Packaging Labor % | O10: =O9/O11 -> 0.46632123 | Q10: Packaging Labor % | S10: =S9/S11 -> 0.27506557 | U10: Packaging Labor % | W10: =W9/W11 -> 0.30260485
A11: Size (g) | B11: 1 | C11: 0.35 | D11: Ceramic | G11: Required Flower (Monthly) | H11: =H9*C11 -> 58800 | I11: =B11*I9 -> 126000 | J11: =(B11*J9)-J15 -> 67200 | K11: =(B11*J9)-J15 -> 67200 | L11: =(B11*L9)-L15 -> 52920 | N11: Total $ | O11: =O5+O7+O9 -> 3.9929557 | Q11: Total $ | S11: =S5+S7+S9 -> 6.7692949 | U11: Total $ | W11: =W5+W7+W9 -> 6.1532391
A12: Cones Size | B12: 109/26 | C12: 78/26 | D12: 90/26 | G12: Infusion Strength | J12: 0.2 | K12: 0.3 | L12: 0.3 | N12: Total % | O12: =O10+O8+O6 -> 1 | Q12: Total % | S12: =S10+S8+S6 -> 1 | U12: Total % | W12: =W10+W8+W6 -> 1
A13: Price Per Cone | B13: 0.06 | C13: 0.06 | D13: 0.89 | G13: Percent Flower | J13: =1-J12 -> 0.8 | K13: =1-K12 -> 0.7 | L13: =1-L12 -> 0.7
A14: Flower Price (lb) | B14: =E5 -> 660 | G14: Required Infusion (g) Daily | J14: =J7*J12 -> 840 | K14: =K7*K12 -> 1260 | L14: =L12*L7 -> 1134
A15: Price Per Gram (w/15% loss to milling) | B15: =B14/386 -> 1.7098446 | D15: % of total = | E15: =B15/I21 -> 0.77228484 | G15: Required Infusion (g) Monthly | J15: =J12*J9 -> 16800 | K15: =K12*K9 -> 25200 | L15: =(L12*L9) -> 22680 | O15: Calculation done to include 15% processing loss
A16: Required Flower (Daily) | B16: =I7*B11 -> 6300 | C16: =H7*C11 -> 2940 | N16: PreRoll Formulations (TG) | O16: Flower Wholesale Price (386g) | P16: Cost Per Gram (F) | Q16: Cost per Gram (T) | R16: Total Cost w/cone | S16: Roll, Mill, QC Labor | T16: Packaging Per PreRoll | U16: Total Cost to Produce | V16: Joint Wholesale Price | W16: Profit (Per Unit)
A17: Required Flower (Monthly) | B17: =B16*B6 -> 126000 | C17: =C16*B6 -> 58800 | N17: 100% Flower | O17: 1200 | P17: =O17/386 -> 3.1088083 | Q17: 0 | R17: =(O17/386)+B13 -> 3.1688083 | S17: =(B7/I6)+D45+D44 -> 0.048040627 | T17: 2.18 | U17: =R17+S17+T17 -> 5.3968489 | V17: 3.5 | W17: =V17-U17 -> -1.8968489
A18: Infusion Material | B18: Bubble Hash | C18: Diamonds | D18: Liquid Diamonds | G18: Per Unit Revenue | N18: 70/30 (Flower to Trim | O18: 930 | P18: =R18*0.7 -> 1.7285285 | Q18: =R18*0.3 -> 0.74079793 | R18: =(O18/386)+B13 -> 2.4693264 | S18: =(B7/I6)+D45+D44 -> 0.048040627 | T18: 2.18 | U18: =R18+S18+T18 -> 4.6973671 | V18: 3.5 | W18: =V18-U18 -> -1.1973671
A19: Price Per Gram | B19: ='H2O IN_OUT'!H18 -> 13.705389 | C19: ='Volatile IN_OUT'!H15 -> 6.0922707 | D19: ='Volatile IN_OUT'!H18 -> 7.7295426 | G19: Product Size | H19: .35g x 5 | I19: 1.0g | J19: 1g (bubble hash) | K19: 1g (micro diamonds) | L19: 1g (injection) | N19: 50/50 (Flower:Trim) | O19: 750 | P19: =R19*0.5 -> 1.0015026 | Q19: =R19*0.5 -> 1.0015026 | R19: =(O19/386)+B13 -> 2.0030052 | S19: =(B7/I6)+D45+D44 -> 0.048040627 | T19: 2.18 | U19: =R19+S19+T19 -> 4.2310458 | V19: 3.5 | W19: =V19-U19 -> -0.73104581
A20: Price Per joint | B20: =B19*J12 -> 2.7410778 | C20: =C19*K12 -> 1.8276812 | D20: =D19*L12 -> 2.3188628 | G20: Wholesale Price | H20: 12 | I20: 5 | J20: 7.5 | K20: 9.5 | L20: 9.5
A21: Total Oil Used (Daily) | B21: =J6*J12 -> 120 | C21: =J6*J12 -> 120 | D21: =L12*L7 -> 1134 | G21: Cost to Produce (w/packaging and labor) | H21: =(H2+(B7/H6))*5 -> 3.5866724 | I21: =I2+(B7/I6)+D35+D47 -> 2.2140077 | J21: =J2+(B7/J6) -> 5.0989534 | K21: =K2+D35+D47 -> 4.3742911 | L21: =L2+D35+D47 -> 4.9903469
A22: Cost to Infuse (Daily) | B22: =B21*B19 -> 1644.6467 | C22: =C21*C19 -> 731.07249 | D22: =D21*D19 -> 8765.3013 | G22: Profit | H22: =H20-H21 -> 8.4133276 | I22: =I20-I21 -> 2.7859923 | J22: =J20-J21 -> 2.4010466 | K22: =K20-K21 -> 5.1257089 | L22: =L20-L21 -> 4.5096531 | N22: PreRoll Formulations (B grade) | O22: Flower Wholesale Price (386g) | P22: Cost (F) | Q22: Cost (T) | R22: Total Cost w/cone | S22: Roll, Mill, QC Labor | T22: Packaging Per PreRoll | U22: Total Cost to Produce | V22: Joint Wholesale Price | W22: Profit (Per Unit)
A23: Total Oil Used (Monthly) | B23: =J15 -> 16800 | C23: =K15 -> 25200 | D23: =L15 -> 22680 | G23: Margin per unit | H23: =H22/H20 -> 0.70111063 | I23: =I22/I20 -> 0.55719847 | J23: =J22/J20 -> 0.32013954 | K23: =K22/K20 -> 0.53954831 | L23: =L22/L20 -> 0.47470032 | N23: 50/50 (Flower:Trim) | O23: 750 | P23: =R23*0.5 -> 1.0015026 | Q23: =R23*0.5 -> 1.0015026 | R23: =(O23/386)+0.06 -> 2.0030052 | S23: =S18 -> 0.048040627 | T23: =(D46-D43+D44)+D34 -> 0.22342952 | U23: =R23+S23+T23 -> 2.2744753 | V23: 2.5 | W23: =V23-U23 -> 0.22552468
A24: Total Cost of Oil (Monthly) | B24: =B23*B19 -> 230250.53 | C24: =C23*C19 -> 153525.22 | D24: =D23*D19 -> 175306.03 | N24: 40/60 (Flower:Trim) | O24: 660 | P24: =(R24-0.06)*0.3 -> 0.51295337 | Q24: =(R24-0.06)*0.7 -> 1.1968912 | R24: =O24/386+0.06 -> 1.7698446 | S24: =S18 -> 0.048040627 | T24: =T23 -> 0.22342952 | U24: =R24+S24+T24 -> 2.0413147 | V24: 2.5 | W24: =V24-U24 -> 0.4586853
N25: 30/70 (Flower:Trim) | O25: 570 | P25: =(R25-0.06)*0.3 -> 0.44300518 | Q25: =(R25-0.06)*0.7 -> 1.0336788 | R25: =O25/386+0.06 -> 1.5366839 | S25: =S19 -> 0.048040627 | T25: =T24 -> 0.22342952 | U25: =R25+S25+T25 -> 1.8081541 | V25: 2.5 | W25: =V25-U25 -> 0.69184592
N26: Liquid Diamond Economy | R26: Micro Diamond Economy
A27: Total printable labels per ribbon | B27: =(984*12)/2.25 -> 5248 | C27: 2 labels/sec
A28: Packaging Costs | N28: Cost Percents (1 g 30% LD Infused preroll) | R28: Cost Percents (1 g 30% M.D Infused preroll)
A29: Consumables | N29: 50/50 Flower @ $1200/lb Trim @ $300/lb | R29: 50/50 Flower @ $1200/lb Trim @ $300/lb | V29: Cost Percents (1 g 30% LD+Terp Infused preroll)
A30: Glass Tube | B30: Per case | C30: Per Roll | D30: Per Unit | F30: 12 x 9 x 6 Corrugated Box = $0.67 per 100 units | N30: Rolling Materials + Labor $ | P30: =R24+S24 -> 1.8178852 | R30: Rolling Materials + Labor $ | T30: =R24+S24 -> 1.8178852 | V30: 30/70 Flower @ $1200/lb Trim @ $300/lb
A31: Cost per label | D31: {=IFS(A30="Plastic Tube",0,A30="Glass Tube",0.07)} -> 0.07 | F31: 6 x 6 x 6 Corrugated Box = $0.39 per 48 or 50 units | N31: Rolling Materials + Labor % | P31: =P30/P39 -> 0.42122135 | R31: Rolling Materials + Labor % | T31: =T30/T39 -> 0.47569112 | V31: Rolling Materials + Labor $ | X31: =R25+S25 -> 1.5847246
A32: Cost per batch sticker | B32: {=IFS(A30="Plastic Tube",91.96,A30="Glass Tube",695.68)} -> 695.68 | C32: {=IFS(A30="Plastic Tube",11.495,A30="Glass Tube",86.96)} -> 86.96 | D32: {=IFS(A30="Plastic Tube",0.009,A30="Glass Tube",0.022)} -> 0.022 | N32: Infusion Strength | P32: 0.3 | R32: Infusion Strength | T32: 0.3 | V32: Rolling Materials + Labor % | X32: =X31/X42 -> 0.40217342
A33: Cost of ribbon | B33: {=IFS(A30="Plastic Tube",68.82,A30="Glass Tube",1171.51)} -> 1171.51 | C33: =B33/12 -> 97.625833 | D33: =C33/B27 -> 0.018602483 | N33: Infusion Cost (Used Value from Material Costs Table) | P33: =D19*P32 -> 2.3188628 | R33: Infusion Cost (Used Value from Material Costs Table) | T33: =C19*T32 -> 1.8276812 | V33: Infusion Strength | X33: 0.3
A34: Cost of tube and top | D34: {=IFS(A30="Plastic Tube",0.055,A30="Glass Tube",0.21)} -> 0.21 | N34: Infusion Cost % | P34: =P33/P39 -> 0.53730264 | R34: Infusion Cost Percent | T34: =T33/T39 -> 0.47825447 | V34: Terp Dilution | X34: 0.1
A35: Totals | B35: =SUM(B32:B34) -> 1867.19 | C35: =SUM(C32:C34) -> 184.58583 | D35: =SUM(D31:D34) -> 0.32060248 | N35: Packaging Materials $ | P35: 0.113 | R35: Packaging Materials $ | T35: 0.11 | V35: Terp Cost (per gram) | X35: 2.99
C36: % of total = | D36: =D35/I21 -> 0.1448064 | N36: Packaging Materials % | P36: =P35/P39 -> 0.026183179 | R36: Packaging Materials % | T36: =T35/T39 -> 0.028784009 | V36: Infusion Cost (Used Value from Material Costs Table) | X36: =(((D19)*(1-X34))+(X34*X35))*X33 -> 2.1766765
A37: Labor @$18/hr | N37: Packaging Labor $ | P37: 0.066 | R37: Packaging Labor $ | T37: 0.066 | V37: Infusion Cost % | X37: =X36/X42 -> 0.55239973
A38: For 1000 pieces | B38: avg time (hours) | C38: Cost per 1000 | D38: Cost per unit | E38: Percents | N38: Packaging Labor % | P38: =P37/P39 -> 0.01529283 | R38: Packaging Labor % | T38: =T37/T39 -> 0.017270405 | V38: Packaging Materials $ | X38: 0.113
A39: Print Time (per 1000 pcs) | B39: 0.14 | C39: =B39*18 -> 2.52 | D39: =C39/1000 -> 0.00252 | E39: =D39/D47 -> 0.02725812 | N39: Total $ | P39: =P30+P35+P37+P33 -> 4.315748 | R39: Total $ | T39: =T30+T35+T37+T33 -> 3.8215664 | V39: Packaging Materials % | X39: =X38/X42 -> 0.028677284
A40: Application of Sticker (1000 pcs) | B40: =(5/60)*4 -> 0.33333333 | C40: =B40*18 -> 6 | D40: =C40/1000 -> 0.006 | E40: =D40/D47 -> 0.064900286 | N40: Total % | P40: =P38+P36+P31+P34 -> 1 | R40: Total % | T40: =T38+T36+T31+T34 -> 1 | V40: Packaging Labor $ | X40: 0.066
...

Sheet PreGround ()
A1: Pre Ground Flower COGS
A2: Materials: | D2: Formulation: | K2: Hydrocarbon (THCa) | N2: Solventless (BubbleHash)
A3: cost of flower (per lb) | B3: 1200 | D3: Infusion Type: | E3: THCa | G3: TAC Calculator | K3: Single Batch Figures (1batch = 15lbs) | N3: Single Batch Figures (1batch = 45lbs)
A4: cost of trim (per lb) | B4: 300 | D4: Cost of Infusion per gram (from respective worksheet) | E4: =IF(LOWER(E3)="thca", L17, IF(LOWER(E3)="bubble hash", O20, "")) -> 5.8048458 | G4: Flower THCa % | H4: 0.22 | K4: Run Size (g) | L4: 6810 | N4: Moisture Correction Price Calculator
A5: corrected price per lb | B5: =(B3*(1-B6))+(B4*B6) -> 909.93 | D5: Infusion Strength | E5: 0.2 | G5: Flower Mass | H5: =(454*(1-E5)) -> 363.2 | I5: grams | K5: Trim Cost (lb) | L5: 300 | N5: Target Flower Price (Dry) | O5: 1200
A6: avg trim yield | B6: 0.3223 | D6: Cost of Infusion (1g) | E6: =E4*E5 -> 1.1609692 | G6: Base Infusion THCa% | H6: =IF(LOWER(E3)="thca", 95%, IF(LOWER(E3)="bubble hash", 50%, "")) -> 0.95 | K6: Trim cost (g) @$300/lb | L6: =L5/454 -> 0.66079295 | N6: Target Trim Price Price (Dry) | O6: 300
A7: adjusted cost (pre infusion) | B7: =(B3*(1-B6))+(B4*B6) -> 909.93 | D7: Required Infusion Mass | E7: =454*E5 -> 90.8 | F7: grams | G7: Infusion Mass | H7: =454-H5 -> 90.8 | I7: grams | K7: Batch Cost | L7: =L6*L4 -> 4500 | N7: Avg Trim Yield | O7: 0.3223
A8: Corrected cost w/infusion | B8: =B7*(1-E5) -> 727.944 | D8: Cost to Infuse (1lb) | E8: =(454*E5)*E4 -> 527.08 | K8: Extraction Labor | L8: 50 | N8: Cost Allocated Price Per Lb (Dry) | O8: =(O5*(1-O7))+(O6*O7) -> 909.93
D9: Total for 1lb Infused Materal: | E9: =B8+E8 -> 1255.024 | G9: Expected THCa % | H9: =((H4*H5)+(H7*H6))/(H7+H5) -> 0.366 | K9: Solvent Cost | L9: 13.72 | N9: Fresh Frozen Per Lb Price | O9: =O8*0.2 -> 181.986
K10: Processing Labor (badder) | L10: 320 | N10: Run Size (g) | O10: =45*454 -> 20430
A11: Packaging | B11: 7.0 grams | D11: Packaging Labor | E11: Unlabeled | K11: Processing Labor Diamonds | L11: 180 | N11: flower cost (g) | O11: =O9/454 -> 0.40085022
A12: Mylar Bags | B12: ---- | D12: Labor Rate | E12: 18 | K12: Avg Crude Yield (10-18%) | L12: 0.12 | N12: Batch Cost | O12: =O11*O10 -> 8189.37
A13: Labels | B13: --- | D13: Label Application? | E13: --- | K13: Crude Oil Yield (g) | L13: =L4*L12 -> 817.2 | N13: Extraction Labor | O13: 140
A14: Batch Sticker | B14: 0.0032995595 | D14: Batch Sticker Application | E14: --- | K14: Avg Yield % to Diamonds | L14: 0.0737 | N14: Solvent (H20) Cost | O14: 0.735
A15: Ribbon/Ink | B15: 0.1064803 | D15: FIlling | E15: --- | K15: Diamond Yield (g) | L15: =L13*L14 -> 60.22764 | N15: Processing Labor(Dry and Sift) | O15: 40
A16: Master Case (Branded) | B16: ---- | D16: Packing (Master Case) | E16: --- | K16: Cost Allocation to Diamonds | L16: =(L7+L8+L9+L11)*L14 -> 349.61216 | N16: Processing Labor (Rosin Packing) | O16: 80
A17: Master Case (Unbranded) | B17: ---- | D17: Compliance Testing | E17: --- | K17: per gram price (THCa) | L17: =L16/L15 -> 5.8048458 | N17: Avg Bubble Yield % | O17: 0.15
A18: Total | D18: Total | K18: Liquid Diamond Yield | L18: =L15*0.877 -> 52.81964 | N18: Bubble Hash Yield (g) | O18: =O10*O17 -> 3064.5
K19: cost allocation to liquid diamonds | L19: =(L7+L8+L9+L11)*(L14) -> 349.61216 | N19: Cost Of Bubble Hash | O19: =O12+O13+O14+O15 -> 8370.105
K20: per gram price | L20: =L19/L18 -> 6.6189804 | N20: per gram price | O20: =O19/O18 -> 2.7313118
K21: Remaing % Crude | L21: =100%-L14 -> 0.9263 | N21: Yield To Rosin % | O21: 0.81
A22: Need to determine: | B22: (Monday meeting) | K22: Remaining Crude (g) | L22: =L13-L15 -> 756.97236 | N22: Rosin Yield (g) | O22: =O18*O21 -> 2482.245
A23: Cost of primary packaging | K23: cost allocation to crude | L23: =(L21*L7)+(L21*L8)+(L9*L21)+L10 -> 4547.3738 | N23: cost allocation to Rosin | O23: =O12+O13+O14+O15+O16 -> 8450.105
A24: Pre Labeled Packaging or Unlabeled | K24: per gram cost | L24: =L23/L22 -> 6.0073182 | N24: per gram cost | O24: =O23/O22 -> 3.4042188
A25: Cost of Labels
A26: Shipping Box Format (Branded or Plain Corrugated)

Sheet Sku list 
A1: Cultivation | D1: Manufacturing
A2: Infused Flower | B2: Concentrate(BHO) | D2: Concentrate (IWH) | F2: PreRoll | G2: Carts
A3: Moon Rocks | D3: 3-4* bubble | F3: .35g x 10 | G3: Live resin | H3: .5g/1g disp
B4: Badder | C4: .5/1g | D4: 5* bubble | F4: 1g x5 | G4: liquid diamonds | H4: .5g/1g cart
B5: Shatter | C5: .5/1g | D5: Rosin | F5: 1g inf/raw | G5: rosin | H5: .5g cart
B6: Live Resin | C6: .5/1g | D6: Live Rosin | G6: live rosin | H6: .5g disposable
B7: Sugar | C7: .5/1g | D7: infusion material | F7: 1g blunt (I,r)
B8: Diamonds | C8: .5/1g | F8: 3-4g blunt (i)
B9: H.T.E | C9: .5/1g
A12: PreRoll Packaging
A13: Plastic Tube
A14: Glass Tube

Sheet Sheet1
A1: INPUTS
A2: BIOMASS PROCESSED DAILY | B2: =B7*B21 -> 43584 | C2: grams | D2: =B2*5 -> 217920 | E2: gram/week
A3: EFFICIENCY | B3: 1 | C3: efficiency | G3: Daily Operations Crude
A4: INPUT BIOMASS COST | B4: 0.67 | C4: per gram | D4: *from 253organic $120/lb trim | G4: Raw material costs | H4: =(B2*B4) -> 29201.28
A5: WHOLE SALE PRICE CRUDE | B5: 4 | C5: per gram | G5: Labor Costs | H5: =B16*B14 -> 400
A6: LUNA.IO YIELD | B6: 0.14 | C6: yield | G6: Consumables Cost per day | H6: =(B13*B21)*B12 -> 24
A7: BIOMASS CAPACITY PER RUN | B7: =20*454 -> 9080 | C7: grams | G7: Subtotal Daily Operating Costs | H7: =H4+H5+H6 -> 29625.28
A8: DISTILLATE WHOLESLE | B8: 7 | C8: per mL
A9: CRUDE TO DISTILLATE | B9: 1 | C9: of crude
A10: SINNING BAND FLOW RATE | B10: 2500 | C10: mL/hour
A11: SPIN.BAND YIELD1 | B11: 0.6 | C11: yield
A12: LPG PRICE | B12: 5 | C12: per lb | D12: * from QualityExtractionGroup
A13: GAS CONSUMPTION RATE | B13: 1 | C13: lbs/run
A14: LABOR RATE | B14: 50 | C14: hr
A15: WORK DAYS/YEAR | B15: 250 | C15: days/year
A16: HOURS OF OPERATION | B16: 8 | C16: hrs
A17: Setup Time | B17: 2 | C17: Hrs
A18: LUNA OUTPUT CRUDE OIL | G18: Gas consumption per run | H18: 2 | I18: lb
A19: Run Duration | B19: 1.25 | C19: hour | G19: number of runs a day | H19: 8 | I19: runs
A20: WorkDay | B20: =B16-B17 -> 6 | C20: hours | G20: number of runs a week | H20: 40 | I20: runs/wk
A21: Total runs daily | B21: =B20/B19 -> 4.8 | C21: runs/day | G21: gas cosumption a week | H21: =H18*H20 -> 80
A22: Daily Production | B22: =B2*(B6*B3) -> 6101.76 | C22: g/day | H22: 80lbs every 2 weeks
A23: Yearly Production | B23: =B22*250 -> 1525440 | C23: g/year
A26: Crude Production Margin
A27: Cost of production | B27: =((B4*B2)+(B14*B16)+((B13*B21)*B12))/B22 -> 4.8552024 | C27: g crude oil
A28: Revenue | B28: =B5*B22 -> 24407.04 | C28: day
A29: Gross(daily) | B29: =B28-(B27*B22) -> -5218.24 | C29: day
A30: Margin | B30: =(B28-(B27*B22))/B28 -> -0.21380061
A32: Daily Distillate Production w/X% commitment of crude (using a 1:1 conversion; gram to mL)
A33: Crude Input | B33: =(B9*B22) -> 6101.76 | C33: g
A34: Daily Distillate Yield | B34: =(B33*B9)*B11 -> 3661.056 | C34: mL
A35: Added Process time | B35: =B33/B10 -> 2.440704 | C35: hours
A36: Cost of production | B36: =(((B14*B16)+(B35*B14))/B34)+B27 -> 4.9977939 | C36: per mL | D36: **calculation does not include winterization or decarboxylation steps
A37: Revenue | B37: =B34*B8 -> 25627.392 | C37: daily
A38: Gross | B38: =B37-(B36*B34) -> 7330.1888 | C38: daily
A39: Margin | B39: =(B37-(B36*B34))/B37 -> 0.28602945
A41: Distillate Yield Annual | B41: =B34*B15 -> 915264 | C41: mL/year
A42: Distillate Cost of Production Annual | B42: =B36*B41 -> 4574300.8 | C42: per year
A43: Distillate Revenue Annual | B43: =B41*B8 -> 6406848 | C43: per year
A44: Distillate Gross Annual | B44: =(B43-B42) -> 1832547.2 | C44: per year
...
